Workbook

Sheet Resource Sheet
A1: NutriLens — Resource Sheet
A2: CS4044 – Fundamentals of Project Management | Spring 2026 | FAST-NUCES
A4: # | B4: Resource Name | C4: Role | D4: Type | E4: Std. Rate (USD/hr) | F4: Ovt. Rate (USD/hr) | G4: USD→PKR | H4: Std. Rate (PKR/hr) | I4: Ovt. Rate (PKR/hr) | J4: Hrs/Day | K4: Notes
A5: 1 | B5: Project Manager (PM) | C5: Planning & Coordination | D5: Work | E5: 8 | F5: 12 | G5: 278 | H5: =E5*G5 -> 2224 | I5: =F5*G5 -> 3336 | J5: 8 | K5: Oversees schedule, risk, stakeholders
A6: 2 | B6: ML Engineer | C6: Machine Learning & AI | D6: Work | E6: 10 | F6: 15 | G6: 278 | H6: =E6*G6 -> 2780 | I6: =F6*G6 -> 4170 | J6: 8 | K6: MobileNetV2, TFLite, A* planner, Gemini
A7: 3 | B7: Backend Developer | C7: Flask API & Firebase | D7: Work | E7: 8 | F7: 12 | G7: 278 | H7: =E7*G7 -> 2224 | I7: =F7*G7 -> 3336 | J7: 8 | K7: REST API, Firestore, Gemini integration
A8: 4 | B8: Flutter Developer | C8: Mobile Frontend | D8: Work | E8: 8 | F8: 12 | G8: 278 | H8: =E8*G8 -> 2224 | I8: =F8*G8 -> 3336 | J8: 8 | K8: All Flutter screens, state management
A9: 5 | B9: QA Engineer | C9: Testing & Quality | D9: Work | E9: 5 | F9: 8 | G9: 278 | H9: =E9*G9 -> 1390 | I9: =F9*G9 -> 2224 | J9: 8 | K9: Unit, integration, UAT, performance tests
A10: 6 | B10: UI/UX Designer | C10: Design & Prototyping | D10: Work | E10: 6 | F10: 9 | G10: 278 | H10: =E10*G10 -> 1668 | I10: =F10*G10 -> 2502 | J10: 8 | K10: Wireframes, high-fi mockups, style guide
A11: 7 | B11: DevOps Engineer | C11: CI/CD & Deployment | D11: Work | E11: 7 | F11: 10 | G11: 278 | H11: =E11*G11 -> 1946 | I11: =F11*G11 -> 2780 | J11: 8 | K11: Railway/Render, GitHub CI/CD, monitoring
A13: * USD→PKR rate: 1 USD = 278 PKR (Mar 2026 assumption). Blue = hardcoded inputs. Yellow = exchange rate cell.

Sheet Cost Sheet
A1: NutriLens — Time-Phased Detailed Cost Sheet
A2: Project: Mar 1 2026 – Oct 29 2026 | 8 hrs/day | 10% Contingency | 15% Overhead | Rates in USD
A4: Phase | B4: Date Range | C4: Resource | D4: Days | E4: Hrs/Day | F4: Rate ($/hr) | G4: Labor (USD) | H4: Contingency (10%) | I4: Overhead (15%) | J4: Phase Total (USD)
A5: Initiation & Planning | B5: Mar 2 – Apr 23 | C5: PM | D5: 38 | E5: 8 | F5: 8 | G5: =D5*E5*F5 -> 2432
C6: ML Engineer | D6: 5 | E6: 8 | F6: 10 | G6: =D6*E6*F6 -> 400
C7: Backend Developer | D7: 3 | E7: 8 | F7: 8 | G7: =D7*E7*F7 -> 192
C8: DevOps Engineer | D8: 2 | E8: 8 | F8: 7 | G8: =D8*E8*F8 -> 112
C9: Phase Subtotal | G9: =SUM(G5,G6,G7,G8) -> 3136 | H9: =G9*0.1 -> 313.6 | I9: =G9*0.15 -> 470.4 | J9: =G9+H9+I9 -> 3920
A11: Design | B11: Mar 2 – May 11 | C11: UI/UX Designer | D11: 30 | E11: 8 | F11: 6 | G11: =D11*E11*F11 -> 1440
C12: Backend Developer | D12: 15 | E12: 8 | F12: 8 | G12: =D12*E12*F12 -> 960
C13: ML Engineer | D13: 8 | E13: 8 | F13: 10 | G13: =D13*E13*F13 -> 640
C14: PM | D14: 6 | E14: 8 | F14: 8 | G14: =D14*E14*F14 -> 384
C15: Phase Subtotal | G15: =SUM(G11,G12,G13,G14) -> 3424 | H15: =G15*0.1 -> 342.4 | I15: =G15*0.15 -> 513.6 | J15: =G15+H15+I15 -> 4280
A17: ML Development | B17: Apr 24 – Jun 17 | C17: ML Engineer | D17: 35 | E17: 8 | F17: 10 | G17: =D17*E17*F17 -> 2800
C18: DevOps Engineer | D18: 3 | E18: 8 | F18: 7 | G18: =D18*E18*F18 -> 168
C19: QA Engineer | D19: 5 | E19: 8 | F19: 5 | G19: =D19*E19*F19 -> 200
C20: Phase Subtotal | G20: =SUM(G17,G18,G19) -> 3168 | H20: =G20*0.1 -> 316.8 | I20: =G20*0.15 -> 475.2 | J20: =G20+H20+I20 -> 3960
A22: Backend Development | B22: May 12 – Aug 21 | C22: Backend Developer | D22: 68 | E22: 8 | F22: 8 | G22: =D22*E22*F22 -> 4352
C23: ML Engineer | D23: 10 | E23: 8 | F23: 10 | G23: =D23*E23*F23 -> 800
C24: QA Engineer | D24: 15 | E24: 8 | F24: 5 | G24: =D24*E24*F24 -> 600
C25: DevOps Engineer | D25: 8 | E25: 8 | F25: 7 | G25: =D25*E25*F25 -> 448
C26: PM | D26: 5 | E26: 8 | F26: 8 | G26: =D26*E26*F26 -> 320
C27: Phase Subtotal | G27: =SUM(G22,G23,G24,G25,G26) -> 6520 | H27: =G27*0.1 -> 652 | I27: =G27*0.15 -> 978 | J27: =G27+H27+I27 -> 8150
A29: Frontend Flutter Dev | B29: Jun 18 – Jul 28 | C29: Flutter Developer | D29: 27 | E29: 8 | F29: 8 | G29: =D29*E29*F29 -> 1728
C30: UI/UX Designer | D30: 8 | E30: 8 | F30: 6 | G30: =D30*E30*F30 -> 384
C31: QA Engineer | D31: 5 | E31: 8 | F31: 5 | G31: =D31*E31*F31 -> 200
C32: Backend Developer | D32: 5 | E32: 8 | F32: 8 | G32: =D32*E32*F32 -> 320
C33: Phase Subtotal | G33: =SUM(G29,G30,G31,G32) -> 2632 | H33: =G33*0.1 -> 263.2 | I33: =G33*0.15 -> 394.8 | J33: =G33+H33+I33 -> 3290
A35: Testing & QA | B35: Aug 24 – Oct 2 | C35: QA Engineer | D35: 29 | E35: 8 | F35: 5 | G35: =D35*E35*F35 -> 1160
C36: Flutter Developer | D36: 10 | E36: 8 | F36: 8 | G36: =D36*E36*F36 -> 640
C37: ML Engineer | D37: 5 | E37: 8 | F37: 10 | G37: =D37*E37*F37 -> 400
C38: Backend Developer | D38: 5 | E38: 8 | F38: 8 | G38: =D38*E38*F38 -> 320
C39: DevOps Engineer | D39: 3 | E39: 8 | F39: 7 | G39: =D39*E39*F39 -> 168
C40: PM | D40: 5 | E40: 8 | F40: 8 | G40: =D40*E40*F40 -> 320
C41: Phase Subtotal | G41: =SUM(G35,G36,G37,G38,G39,G40) -> 3008 | H41: =G41*0.1 -> 300.8 | I41: =G41*0.15 -> 451.2 | J41: =G41+H41+I41 -> 3760
A43: Deployment | B43: Jul 29 – Aug 18 | C43: DevOps Engineer | D43: 14 | E43: 8 | F43: 7 | G43: =D43*E43*F43 -> 784
C44: Flutter Developer | D44: 5 | E44: 8 | F44: 8 | G44: =D44*E44*F44 -> 320
C45: Backend Developer | D45: 5 | E45: 8 | F45: 8 | G45: =D45*E45*F45 -> 320
C46: PM | D46: 5 | E46: 8 | F46: 8 | G46: =D46*E46*F46 -> 320
C47: QA Engineer | D47: 3 | E47: 8 | F47: 5 | G47: =D47*E47*F47 -> 120
...

Sheet Summary
A1: NutriLens — Project Budget Summary
A2: CS4044 – Fundamentals of Project Management | Spring 2026
A4: 1 | B4: Project Name | C4: NutriLens – AI-Powered Food & Macro Tracker
A5: 2 | B5: Organization | C5: FAST-NUCES Karachi
A6: 3 | B6: Course | C6: CS4044 – Fundamentals of Project Management
A7: 4 | B7: Start Date | C7: 2nd March 2026
A8: 5 | B8: End Date | C8: 29th October 2026
A9: 6 | B9: Duration | C9: ~8 Months
A10: 7 | B10: Team Size | C10: 7 Resources
A11: 8 | B11: Contingency | C11: 10% per phase
A12: 9 | B12: Overhead | C12: 15% per phase (cloud, APIs, licenses)
A13: 10 | B13: Exchange Rate | C13: 1 USD = 278 PKR
A15: # | B15: Phase | C15: Date Range | D15: Days | E15: Labor (USD) | F15: Phase Total (USD) | G15: Phase Total (PKR)
A16: 1 | B16: Initiation & Planning | C16: Mar 2 – Apr 23 | D16: 38 | E16: ='Cost Sheet'!G9 -> 3136 | F16: ='Cost Sheet'!J9 -> 3920 | G16: ='Cost Sheet'!J9*278 -> 1089760
A17: 2 | B17: Design | C17: Mar 2 – May 11 | D17: 49 | E17: ='Cost Sheet'!G15 -> 3424 | F17: ='Cost Sheet'!J15 -> 4280 | G17: ='Cost Sheet'!J15*278 -> 1189840
A18: 3 | B18: ML Development | C18: Apr 24 – Jun 17 | D18: 35 | E18: ='Cost Sheet'!G20 -> 3168 | F18: ='Cost Sheet'!J20 -> 3960 | G18: ='Cost Sheet'!J20*278 -> 1100880
A19: 4 | B19: Backend Development | C19: May 12 – Aug 21 | D19: 68 | E19: ='Cost Sheet'!G27 -> 6520 | F19: ='Cost Sheet'!J27 -> 8150 | G19: ='Cost Sheet'!J27*278 -> 2265700
A20: 5 | B20: Frontend Flutter Dev | C20: Jun 18 – Jul 28 | D20: 27 | E20: ='Cost Sheet'!G33 -> 2632 | F20: ='Cost Sheet'!J33 -> 3290 | G20: ='Cost Sheet'!J33*278 -> 914620
A21: 6 | B21: Testing & QA | C21: Aug 24 – Oct 2 | D21: 29 | E21: ='Cost Sheet'!G41 -> 3008 | F21: ='Cost Sheet'!J41 -> 3760 | G21: ='Cost Sheet'!J41*278 -> 1045280
A22: 7 | B22: Deployment | C22: Jul 29 – Aug 18 | D22: 14 | E22: ='Cost Sheet'!G48 -> 1864 | F22: ='Cost Sheet'!J48 -> 2330 | G22: ='Cost Sheet'!J48*278 -> 647740
A23: 8 | B23: Project Closure | C23: Oct 5 – Oct 29 | D23: 19 | E23: ='Cost Sheet'!G53 -> 1688 | F23: ='Cost Sheet'!J53 -> 2110 | G23: ='Cost Sheet'!J53*278 -> 586580
A24: GRAND TOTAL | E24: =SUM(E16:E23) -> 25440 | F24: =SUM(F16:F23) -> 31800 | G24: =SUM(G16:G23) -> 8840400
A26: Key Budget Metrics
A27: Total Labor Cost (USD) | E27: ='Cost Sheet'!G55 -> 25440
A28: Total Contingency (USD) | E28: ='Cost Sheet'!H55 -> 2544
A29: Total Overhead (USD) | E29: ='Cost Sheet'!I55 -> 3816
A30: Grand Total Budget (USD) | E30: ='Cost Sheet'!J55 -> 31800
A31: Grand Total Budget (PKR) | E31: ='Cost Sheet'!J55*278 -> 8840400
A32: Contingency as % of Labor | E32: ='Cost Sheet'!H55/'Cost Sheet'!G55 -> 0.1
A33: Overhead as % of Labor | E33: ='Cost Sheet'!I55/'Cost Sheet'!G55 -> 0.15
A34: Avg. Daily Cost (USD) | E34: ='Cost Sheet'!J55/239 -> 133.05439
A36: * Overhead covers: Railway/Render hosting, Google Gemini API, Firebase Blaze plan, GitHub Pro, Figma, testing devices, and miscellaneous tools.
